Workbook
Name TablesList: Recap!$G$2

Sheet Recap
G2: Tables and Figures | H2: Sheet
F4: InputID | G4: Table / Figure | H4: Go to sheet
F5: sec1_scr_pat | G5: =IFERROR(HYPERLINK("#Labels!G"&MATCH(F5,Labels!D:D,0),IF(INDEX(Labels!H:H,MATCH(F5,Labels!D:D,0))="Yes","Figure "&INDEX(Labels!F:F,MATCH(F5,Labels!D:D,0))&" - "&INDEX(Labels!G:G,MATCH(F5,Labels!D:D,0)),"Table "&INDEX(Labels!F:F,MATCH(F5,Labels!D:D,0))&" - "&INDEX(Labels!G:G,MATCH(F5,Labels!D:D,0)))),"[Not found: "&F5&"]") -> Table 1 - Screened participants | H5: =HYPERLINK("#'sec1_scr_pat'!A1","Open →") -> Open →
F6: sec1_inc_pat | G6: =IFERROR(HYPERLINK("#Labels!G"&MATCH(F6,Labels!D:D,0),IF(INDEX(Labels!H:H,MATCH(F6,Labels!D:D,0))="Yes","Figure "&INDEX(Labels!F:F,MATCH(F6,Labels!D:D,0))&" - "&INDEX(Labels!G:G,MATCH(F6,Labels!D:D,0)),"Table "&INDEX(Labels!F:F,MATCH(F6,Labels!D:D,0))&" - "&INDEX(Labels!G:G,MATCH(F6,Labels!D:D,0)))),"[Not found: "&F6&"]") -> Table 2 - Participants disposition - included participants by study site | H6: =HYPERLINK("#'sec1_inc_pat'!A1","Open →") -> Open →
F7: sec1_inc_ITT_form | G7: =IFERROR(HYPERLINK("#Labels!G"&MATCH(F7,Labels!D:D,0),IF(INDEX(Labels!H:H,MATCH(F7,Labels!D:D,0))="Yes","Figure "&INDEX(Labels!F:F,MATCH(F7,Labels!D:D,0))&" - "&INDEX(Labels!G:G,MATCH(F7,Labels!D:D,0)),"Table "&INDEX(Labels!F:F,MATCH(F7,Labels!D:D,0))&" - "&INDEX(Labels!G:G,MATCH(F7,Labels!D:D,0)))),"[Not found: "&F7&"]") -> Table 3 - Participants disposition - included participants by tablet form - ITT population | H7: =HYPERLINK("#'sec1_inc_ITT'!A1","Open →") -> Open →
F8: sec1_inc_ITT_stage | G8: =IFERROR(HYPERLINK("#Labels!G"&MATCH(F8,Labels!D:D,0),IF(INDEX(Labels!H:H,MATCH(F8,Labels!D:D,0))="Yes","Figure "&INDEX(Labels!F:F,MATCH(F8,Labels!D:D,0))&" - "&INDEX(Labels!G:G,MATCH(F8,Labels!D:D,0)),"Table "&INDEX(Labels!F:F,MATCH(F8,Labels!D:D,0))&" - "&INDEX(Labels!G:G,MATCH(F8,Labels!D:D,0)))),"[Not found: "&F8&"]") -> Table 4 - Participants disposition - included participants by stage - ITT population | H8: =HYPERLINK("#'sec1_inc_ITT'!A1","Open →") -> Open →
F9: sec1_nb_vt | G9: =IFERROR(HYPERLINK("#Labels!G"&MATCH(F9,Labels!D:D,0),IF(INDEX(Labels!H:H,MATCH(F9,Labels!D:D,0))="Yes","Figure "&INDEX(Labels!F:F,MATCH(F9,Labels!D:D,0))&" - "&INDEX(Labels!G:G,MATCH(F9,Labels!D:D,0)),"Table "&INDEX(Labels!F:F,MATCH(F9,Labels!D:D,0))&" - "&INDEX(Labels!G:G,MATCH(F9,Labels!D:D,0)))),"[Not found: "&F9&"]") -> Table 5 - Number of participants by type of visits performed - ITT population | H9: =HYPERLINK("#'sec1_nb_vt'!A1","Open →") -> Open →
F10: sec2_bas_char | G10: =IFERROR(HYPERLINK("#Labels!G"&MATCH(F10,Labels!D:D,0),IF(INDEX(Labels!H:H,MATCH(F10,Labels!D:D,0))="Yes","Figure "&INDEX(Labels!F:F,MATCH(F10,Labels!D:D,0))&" - "&INDEX(Labels!G:G,MATCH(F10,Labels!D:D,0)),"Table "&INDEX(Labels!F:F,MATCH(F10,Labels!D:D,0))&" - "&INDEX(Labels!G:G,MATCH(F10,Labels!D:D,0)))),"[Not found: "&F10&"]") -> Table 7 - Preselection characteristics per weight band -ITT population | H10: =HYPERLINK("#'sec2_bas_char'!A1","Open →") -> Open →
F11: sec2_labdiag | G11: =IFERROR(HYPERLINK("#Labels!G"&MATCH(F11,Labels!D:D,0),IF(INDEX(Labels!H:H,MATCH(F11,Labels!D:D,0))="Yes","Figure "&INDEX(Labels!F:F,MATCH(F11,Labels!D:D,0))&" - "&INDEX(Labels!G:G,MATCH(F11,Labels!D:D,0)),"Table "&INDEX(Labels!F:F,MATCH(F11,Labels!D:D,0))&" - "&INDEX(Labels!G:G,MATCH(F11,Labels!D:D,0)))),"[Not found: "&F11&"]") -> Table 14 - Laboratory diagnosis of HAT at preselection per weight band - ITT population | H11: =HYPERLINK("#'sec2_labdiag'!A1","Open →") -> Open →
F12: sec2_labdiag_tot | G12: =IFERROR(HYPERLINK("#Labels!G"&MATCH(F12,Labels!D:D,0),IF(INDEX(Labels!H:H,MATCH(F12,Labels!D:D,0))="Yes","Figure "&INDEX(Labels!F:F,MATCH(F12,Labels!D:D,0))&" - "&INDEX(Labels!G:G,MATCH(F12,Labels!D:D,0)),"Table "&INDEX(Labels!F:F,MATCH(F12,Labels!D:D,0))&" - "&INDEX(Labels!G:G,MATCH(F12,Labels!D:D,0)))),"[Not found: "&F12&"]") -> Table 13 - Laboratory diagnosis of Hat at preselection total - ITT population | H12: =HYPERLINK("#'sec2_labdiag'!A1","Open →") -> Open →
F13: sec2_mehs_soc | G13: =IFERROR(HYPERLINK("#Labels!G"&MATCH(F13,Labels!D:D,0),IF(INDEX(Labels!H:H,MATCH(F13,Labels!D:D,0))="Yes","Figure "&INDEX(Labels!F:F,MATCH(F13,Labels!D:D,0))&" - "&INDEX(Labels!G:G,MATCH(F13,Labels!D:D,0)),"Table "&INDEX(Labels!F:F,MATCH(F13,Labels!D:D,0))&" - "&INDEX(Labels!G:G,MATCH(F13,Labels!D:D,0)))),"[Not found: "&F13&"]") -> Table 12 - Medical History by SOC/PT - ITT participants | H13: =HYPERLINK("#'sec2_mehs_soc'!A1","Open →") -> Open →
F14: sec2_res_mal | G14: =IFERROR(HYPERLINK("#Labels!G"&MATCH(F14,Labels!D:D,0),IF(INDEX(Labels!H:H,MATCH(F14,Labels!D:D,0))="Yes","Figure "&INDEX(Labels!F:F,MATCH(F14,Labels!D:D,0))&" - "&INDEX(Labels!G:G,MATCH(F14,Labels!D:D,0)),"Table "&INDEX(Labels!F:F,MATCH(F14,Labels!D:D,0))&" - "&INDEX(Labels!G:G,MATCH(F14,Labels!D:D,0)))),"[Not found: "&F14&"]") -> Table 16 - Results of malaria test at preselection per weight band - ITT population | H14: =HYPERLINK("#'sec2_res_mal'!A1","Open →") -> Open →
F15: sec2_vit_sg_tot | G15: =IFERROR(HYPERLINK("#Labels!G"&MATCH(F15,Labels!D:D,0),IF(INDEX(Labels!H:H,MATCH(F15,Labels!D:D,0))="Yes","Figure "&INDEX(Labels!F:F,MATCH(F15,Labels!D:D,0))&" - "&INDEX(Labels!G:G,MATCH(F15,Labels!D:D,0)),"Table "&INDEX(Labels!F:F,MATCH(F15,Labels!D:D,0))&" - "&INDEX(Labels!G:G,MATCH(F15,Labels!D:D,0)))),"[Not found: "&F15&"]") -> Table 17 - Vital signs at baseline total - ITT population | H15: =HYPERLINK("#'sec2_vit_sg'!A1","Open →") -> Open →
F16: sec2_vit_sg | G16: =IFERROR(HYPERLINK("#Labels!G"&MATCH(F16,Labels!D:D,0),IF(INDEX(Labels!H:H,MATCH(F16,Labels!D:D,0))="Yes","Figure "&INDEX(Labels!F:F,MATCH(F16,Labels!D:D,0))&" - "&INDEX(Labels!G:G,MATCH(F16,Labels!D:D,0)),"Table "&INDEX(Labels!F:F,MATCH(F16,Labels!D:D,0))&" - "&INDEX(Labels!G:G,MATCH(F16,Labels!D:D,0)))),"[Not found: "&F16&"]") -> Table 18 - Vital signs at baseline per weight band - ITT population | H16: =HYPERLINK("#'sec2_vit_sg'!A1","Open →") -> Open →
F17: sec2_tsh_tot | G17: =IFERROR(HYPERLINK("#Labels!G"&MATCH(F17,Labels!D:D,0),IF(INDEX(Labels!H:H,MATCH(F17,Labels!D:D,0))="Yes","Figure "&INDEX(Labels!F:F,MATCH(F17,Labels!D:D,0))&" - "&INDEX(Labels!G:G,MATCH(F17,Labels!D:D,0)),"Table "&INDEX(Labels!F:F,MATCH(F17,Labels!D:D,0))&" - "&INDEX(Labels!G:G,MATCH(F17,Labels!D:D,0)))),"[Not found: "&F17&"]") -> Table 19 - Thyroid assessment at screening total - ITT population
F18: sec2_rhat_time | G18: =IFERROR(HYPERLINK("#Labels!G"&MATCH(F18,Labels!D:D,0),IF(INDEX(Labels!H:H,MATCH(F18,Labels!D:D,0))="Yes","Figure "&INDEX(Labels!F:F,MATCH(F18,Labels!D:D,0))&" - "&INDEX(Labels!G:G,MATCH(F18,Labels!D:D,0)),"Table "&INDEX(Labels!F:F,MATCH(F18,Labels!D:D,0))&" - "&INDEX(Labels!G:G,MATCH(F18,Labels!D:D,0)))),"[Not found: "&F18&"]") -> Table 21 - For each Signs and symptoms of HAT at baseline: Time from symptom n (%) | H18: =HYPERLINK("#'sec2_rhat'!A1","Open →") -> Open →
F19: sec2_rhat_grade | G19: =IFERROR(HYPERLINK("#Labels!G"&MATCH(F19,Labels!D:D,0),IF(INDEX(Labels!H:H,MATCH(F19,Labels!D:D,0))="Yes","Figure "&INDEX(Labels!F:F,MATCH(F19,Labels!D:D,0))&" - "&INDEX(Labels!G:G,MATCH(F19,Labels!D:D,0)),"Table "&INDEX(Labels!F:F,MATCH(F19,Labels!D:D,0))&" - "&INDEX(Labels!G:G,MATCH(F19,Labels!D:D,0)))),"[Not found: "&F19&"]") -> Table 22 - For each Signs and symptoms of HAT at baseline: Continuous or interITTent and grade - ITT population n (%) | H19: =HYPERLINK("#'sec2_rhat'!A1","Open →") -> Open →
F20: sec2_otherss_first | G20: =IFERROR(HYPERLINK("#Labels!G"&MATCH(F20,Labels!D:D,0),IF(INDEX(Labels!H:H,MATCH(F20,Labels!D:D,0))="Yes","Figure "&INDEX(Labels!F:F,MATCH(F20,Labels!D:D,0))&" - "&INDEX(Labels!G:G,MATCH(F20,Labels!D:D,0)),"Table "&INDEX(Labels!F:F,MATCH(F20,Labels!D:D,0))&" - "&INDEX(Labels!G:G,MATCH(F20,Labels!D:D,0)))),"[Not found: "&F20&"]") -> Table 23 - For each Other Signs and symptoms of HAT at baseline: Time from symptom
F21: sec2_otherss_sev | G21: =IFERROR(HYPERLINK("#Labels!G"&MATCH(F21,Labels!D:D,0),IF(INDEX(Labels!H:H,MATCH(F21,Labels!D:D,0))="Yes","Figure "&INDEX(Labels!F:F,MATCH(F21,Labels!D:D,0))&" - "&INDEX(Labels!G:G,MATCH(F21,Labels!D:D,0)),"Table "&INDEX(Labels!F:F,MATCH(F21,Labels!D:D,0))&" - "&INDEX(Labels!G:G,MATCH(F21,Labels!D:D,0)))),"[Not found: "&F21&"]") -> Table 24 - For each Other Signs and symptoms of HAT at baseline: Continuous or interITTent and grade -ITT population n (%)
F22: sec2_physex | G22: =IFERROR(HYPERLINK("#Labels!G"&MATCH(F22,Labels!D:D,0),IF(INDEX(Labels!H:H,MATCH(F22,Labels!D:D,0))="Yes","Figure "&INDEX(Labels!F:F,MATCH(F22,Labels!D:D,0))&" - "&INDEX(Labels!G:G,MATCH(F22,Labels!D:D,0)),"Table "&INDEX(Labels!F:F,MATCH(F22,Labels!D:D,0))&" - "&INDEX(Labels!G:G,MATCH(F22,Labels!D:D,0)))),"[Not found: "&F22&"]") -> Table 25 - Physical examination at screening: n (%) of participants with normal / abnormal examination - ITT population | H22: =HYPERLINK("#'sec2_physex'!A1","Open →") -> Open →
F23: sec2_neurex | G23: =IFERROR(HYPERLINK("#Labels!G"&MATCH(F23,Labels!D:D,0),IF(INDEX(Labels!H:H,MATCH(F23,Labels!D:D,0))="Yes","Figure "&INDEX(Labels!F:F,MATCH(F23,Labels!D:D,0))&" - "&INDEX(Labels!G:G,MATCH(F23,Labels!D:D,0)),"Table "&INDEX(Labels!F:F,MATCH(F23,Labels!D:D,0))&" - "&INDEX(Labels!G:G,MATCH(F23,Labels!D:D,0)))),"[Not found: "&F23&"]") -> Table 26 - Neurological examinations at screening: n (%) of participants with anormal / abnormal examination - ITT population | H23: =HYPERLINK("#'sec2_neurex'!A1","Open →") -> Open →
F24: sec2_platelets | G24: =IFERROR(HYPERLINK("#Labels!G"&MATCH(F24,Labels!D:D,0),IF(INDEX(Labels!H:H,MATCH(F24,Labels!D:D,0))="Yes","Figure "&INDEX(Labels!F:F,MATCH(F24,Labels!D:D,0))&" - "&INDEX(Labels!G:G,MATCH(F24,Labels!D:D,0)),"Table "&INDEX(Labels!F:F,MATCH(F24,Labels!D:D,0))&" - "&INDEX(Labels!G:G,MATCH(F24,Labels!D:D,0)))),"[Not found: "&F24&"]") -> Table 27 - Platelets (10^3/µl): n (%) of participants with normal/abnormal results and descriptive statistics - ITT population
F25: sec2_leukocytes | G25: =IFERROR(HYPERLINK("#Labels!G"&MATCH(F25,Labels!D:D,0),IF(INDEX(Labels!H:H,MATCH(F25,Labels!D:D,0))="Yes","Figure "&INDEX(Labels!F:F,MATCH(F25,Labels!D:D,0))&" - "&INDEX(Labels!G:G,MATCH(F25,Labels!D:D,0)),"Table "&INDEX(Labels!F:F,MATCH(F25,Labels!D:D,0))&" - "&INDEX(Labels!G:G,MATCH(F25,Labels!D:D,0)))),"[Not found: "&F25&"]") -> Table 28 - Leukocytes (10^3/µl): n (%) of participants with normal/abnormal results and descriptive statistics - ITT population
F26: sec2_neutrophils | G26: =IFERROR(HYPERLINK("#Labels!G"&MATCH(F26,Labels!D:D,0),IF(INDEX(Labels!H:H,MATCH(F26,Labels!D:D,0))="Yes","Figure "&INDEX(Labels!F:F,MATCH(F26,Labels!D:D,0))&" - "&INDEX(Labels!G:G,MATCH(F26,Labels!D:D,0)),"Table "&INDEX(Labels!F:F,MATCH(F26,Labels!D:D,0))&" - "&INDEX(Labels!G:G,MATCH(F26,Labels!D:D,0)))),"[Not found: "&F26&"]") -> Table 29 - Neutrophils (%): n (%) of participants with normal/abnormal results and descriptive statistics - ITT population
F27: sec2_eosinophils | G27: =IFERROR(HYPERLINK("#Labels!G"&MATCH(F27,Labels!D:D,0),IF(INDEX(Labels!H:H,MATCH(F27,Labels!D:D,0))="Yes","Figure "&INDEX(Labels!F:F,MATCH(F27,Labels!D:D,0))&" - "&INDEX(Labels!G:G,MATCH(F27,Labels!D:D,0)),"Table "&INDEX(Labels!F:F,MATCH(F27,Labels!D:D,0))&" - "&INDEX(Labels!G:G,MATCH(F27,Labels!D:D,0)))),"[Not found: "&F27&"]") -> Table 30 - Eosinophils (%): n (%) of participants with normal/abnormal results and descriptive statistics - ITT population
F28: sec2_basophils | G28: =IFERROR(HYPERLINK("#Labels!G"&MATCH(F28,Labels!D:D,0),IF(INDEX(Labels!H:H,MATCH(F28,Labels!D:D,0))="Yes","Figure "&INDEX(Labels!F:F,MATCH(F28,Labels!D:D,0))&" - "&INDEX(Labels!G:G,MATCH(F28,Labels!D:D,0)),"Table "&INDEX(Labels!F:F,MATCH(F28,Labels!D:D,0))&" - "&INDEX(Labels!G:G,MATCH(F28,Labels!D:D,0)))),"[Not found: "&F28&"]") -> Table 31 - Basophils (%) : n (%) of participants with normal/abnormal results and descriptive statistics - ITT population
F29: sec2_lymphocytes | G29: =IFERROR(HYPERLINK("#Labels!G"&MATCH(F29,Labels!D:D,0),IF(INDEX(Labels!H:H,MATCH(F29,Labels!D:D,0))="Yes","Figure "&INDEX(Labels!F:F,MATCH(F29,Labels!D:D,0))&" - "&INDEX(Labels!G:G,MATCH(F29,Labels!D:D,0)),"Table "&INDEX(Labels!F:F,MATCH(F29,Labels!D:D,0))&" - "&INDEX(Labels!G:G,MATCH(F29,Labels!D:D,0)))),"[Not found: "&F29&"]") -> Table 32 - Lymphocytes (%): n (%) of participants with normal/abnormal results and descriptive statistics - ITT population
F30: sec2_monocytes | G30: =IFERROR(HYPERLINK("#Labels!G"&MATCH(F30,Labels!D:D,0),IF(INDEX(Labels!H:H,MATCH(F30,Labels!D:D,0))="Yes","Figure "&INDEX(Labels!F:F,MATCH(F30,Labels!D:D,0))&" - "&INDEX(Labels!G:G,MATCH(F30,Labels!D:D,0)),"Table "&INDEX(Labels!F:F,MATCH(F30,Labels!D:D,0))&" - "&INDEX(Labels!G:G,MATCH(F30,Labels!D:D,0)))),"[Not found: "&F30&"]") -> Table 33 - Monocytes (%): n (%) of participants with normal/abnormal results and descriptive statistics - ITT population
F31: sec2_hemo_1 | G31: =IFERROR(HYPERLINK("#Labels!G"&MATCH(F31,Labels!D:D,0),IF(INDEX(Labels!H:H,MATCH(F31,Labels!D:D,0))="Yes","Figure "&INDEX(Labels!F:F,MATCH(F31,Labels!D:D,0))&" - "&INDEX(Labels!G:G,MATCH(F31,Labels!D:D,0)),"Table "&INDEX(Labels!F:F,MATCH(F31,Labels!D:D,0))&" - "&INDEX(Labels!G:G,MATCH(F31,Labels!D:D,0)))),"[Not found: "&F31&"]") -> Table 34 - n (%) of participants with normal/abnormal results and descriptive statistics for Hemoglobin– male (g/dL) in ITT population
F32: sec2_hemo_2 | G32: =IFERROR(HYPERLINK("#Labels!G"&MATCH(F32,Labels!D:D,0),IF(INDEX(Labels!H:H,MATCH(F32,Labels!D:D,0))="Yes","Figure "&INDEX(Labels!F:F,MATCH(F32,Labels!D:D,0))&" - "&INDEX(Labels!G:G,MATCH(F32,Labels!D:D,0)),"Table "&INDEX(Labels!F:F,MATCH(F32,Labels!D:D,0))&" - "&INDEX(Labels!G:G,MATCH(F32,Labels!D:D,0)))),"[Not found: "&F32&"]") -> Table 35 - n (%) of participants with normal/abnormal results and descriptive statistics for Hemoglobin– female (g/dL) in ITT population
F33: sec2_sodium | G33: =IFERROR(HYPERLINK("#Labels!G"&MATCH(F33,Labels!D:D,0),IF(INDEX(Labels!H:H,MATCH(F33,Labels!D:D,0))="Yes","Figure "&INDEX(Labels!F:F,MATCH(F33,Labels!D:D,0))&" - "&INDEX(Labels!G:G,MATCH(F33,Labels!D:D,0)),"Table "&INDEX(Labels!F:F,MATCH(F33,Labels!D:D,0))&" - "&INDEX(Labels!G:G,MATCH(F33,Labels!D:D,0)))),"[Not found: "&F33&"]") -> Table 36 - Sodium (mmol/L): n (%) of participants with normal/abnormal results and descriptive statistics - ITT population
F34: sec2_potassium | G34: =IFERROR(HYPERLINK("#Labels!G"&MATCH(F34,Labels!D:D,0),IF(INDEX(Labels!H:H,MATCH(F34,Labels!D:D,0))="Yes","Figure "&INDEX(Labels!F:F,MATCH(F34,Labels!D:D,0))&" - "&INDEX(Labels!G:G,MATCH(F34,Labels!D:D,0)),"Table "&INDEX(Labels!F:F,MATCH(F34,Labels!D:D,0))&" - "&INDEX(Labels!G:G,MATCH(F34,Labels!D:D,0)))),"[Not found: "&F34&"]") -> Table 37 - Potassium (mmol/L): n (%) of participants with normal/abnormal results and descriptive statistics - ITT population
F35: sec2_bicarbonates | G35: =IFERROR(HYPERLINK("#Labels!G"&MATCH(F35,Labels!D:D,0),IF(INDEX(Labels!H:H,MATCH(F35,Labels!D:D,0))="Yes","Figure "&INDEX(Labels!F:F,MATCH(F35,Labels!D:D,0))&" - "&INDEX(Labels!G:G,MATCH(F35,Labels!D:D,0)),"Table "&INDEX(Labels!F:F,MATCH(F35,Labels!D:D,0))&" - "&INDEX(Labels!G:G,MATCH(F35,Labels!D:D,0)))),"[Not found: "&F35&"]") -> Table 38 - Bicarbonates (mmol/L): n (%) of participants with normal/abnormal results and descriptive statistics - ITT population
... F46: sec2_tprotein | G46: =IFERROR(HYPERLINK("#Labels!G"&MATCH(F46,Labels!D:D,0),IF(INDEX(Labels!H:H,MATCH(F46,Labels!D:D,0))="Yes","Figure "&INDEX(Labels!F:F,MATCH(F46,Labels!D:D,0))&" - "&INDEX(Labels!G:G,MATCH(F46,Labels!D:D,0)),"Table "&INDEX(Labels!F:F,MATCH(F46,Labels!D:D,0))&" - "&INDEX(Labels!G:G,MATCH(F46,Labels!D:D,0)))),"[Not found: "&F46&"]") -> Table 49 - Total protein (g/dL) n (%) of participants with normal/abnormal results and descriptive statistics - ITT population
F47: sec2_ecg | G47: =IFERROR(HYPERLINK("#Labels!G"&MATCH(F47,Labels!D:D,0),IF(INDEX(Labels!H:H,MATCH(F47,Labels!D:D,0))="Yes","Figure "&INDEX(Labels!F:F,MATCH(F47,Labels!D:D,0))&" - "&INDEX(Labels!G:G,MATCH(F47,Labels!D:D,0)),"Table "&INDEX(Labels!F:F,MATCH(F47,Labels!D:D,0))&" - "&INDEX(Labels!G:G,MATCH(F47,Labels!D:D,0)))),"[Not found: "&F47&"]") -> Table 50 - ECG at baseline - ITT population | H47: =HYPERLINK("#'sec2_ecg'!A1","Open →") -> Open →
F48: sec3_patdev1 | G48: =IFERROR(HYPERLINK("#Labels!G"&MATCH(F48,Labels!D:D,0),IF(INDEX(Labels!H:H,MATCH(F48,Labels!D:D,0))="Yes","Figure "&INDEX(Labels!F:F,MATCH(F48,Labels!D:D,0))&" - "&INDEX(Labels!G:G,MATCH(F48,Labels!D:D,0)),"Table "&INDEX(Labels!F:F,MATCH(F48,Labels!D:D,0))&" - "&INDEX(Labels!G:G,MATCH(F48,Labels!D:D,0)))),"[Not found: "&F48&"]") -> Table 51 - Participants with a deviation during the treatment administration - ITT population | H48: =HYPERLINK("#'sec3_patdev1'!A1","Open →") -> Open →
F49: sec3_patdev2 | G49: =IFERROR(HYPERLINK("#Labels!G"&MATCH(F49,Labels!D:D,0),IF(INDEX(Labels!H:H,MATCH(F49,Labels!D:D,0))="Yes","Figure "&INDEX(Labels!F:F,MATCH(F49,Labels!D:D,0))&" - "&INDEX(Labels!G:G,MATCH(F49,Labels!D:D,0)),"Table "&INDEX(Labels!F:F,MATCH(F49,Labels!D:D,0))&" - "&INDEX(Labels!G:G,MATCH(F49,Labels!D:D,0)))),"[Not found: "&F49&"]") -> Table 52 - Participants with at least one re-administration of the treatment - ITT population | H49: =HYPERLINK("#'sec3_patdev2'!A1","Open →") -> Open →
F50: sec4_deathstage2_ev | G50: =IFERROR(HYPERLINK("#Labels!G"&MATCH(F50,Labels!D:D,0),IF(INDEX(Labels!H:H,MATCH(F50,Labels!D:D,0))="Yes","Figure "&INDEX(Labels!F:F,MATCH(F50,Labels!D:D,0))&" - "&INDEX(Labels!G:G,MATCH(F50,Labels!D:D,0)),"Table "&INDEX(Labels!F:F,MATCH(F50,Labels!D:D,0))&" - "&INDEX(Labels!G:G,MATCH(F50,Labels!D:D,0)))),"[Not found: "&F50&"]") -> Table 53 - N (%) of death possibly related to r-HAT or to Fexinidazole up to the end of hospitalisation – stage 2 r-HAT participants in the evaluable population
F51: sec4_deathstage2_ITT | G51: =IFERROR(HYPERLINK("#Labels!G"&MATCH(F51,Labels!D:D,0),IF(INDEX(Labels!H:H,MATCH(F51,Labels!D:D,0))="Yes","Figure "&INDEX(Labels!F:F,MATCH(F51,Labels!D:D,0))&" - "&INDEX(Labels!G:G,MATCH(F51,Labels!D:D,0)),"Table "&INDEX(Labels!F:F,MATCH(F51,Labels!D:D,0))&" - "&INDEX(Labels!G:G,MATCH(F51,Labels!D:D,0)))),"[Not found: "&F51&"]") -> Table 54 - Sensitivity analysis: N (%) of death possibly related to r-HAT or to Fexinidazole up to the end of hospitalisation – stage 2 r-HAT participants in the ITT population
F52: sec4_deathstage2 | G52: =IFERROR(HYPERLINK("#Labels!G"&MATCH(F52,Labels!D:D,0),IF(INDEX(Labels!H:H,MATCH(F52,Labels!D:D,0))="Yes","Figure "&INDEX(Labels!F:F,MATCH(F52,Labels!D:D,0))&" - "&INDEX(Labels!G:G,MATCH(F52,Labels!D:D,0)),"Table "&INDEX(Labels!F:F,MATCH(F52,Labels!D:D,0))&" - "&INDEX(Labels!G:G,MATCH(F52,Labels!D:D,0)))),"[Not found: "&F52&"]") -> Table 55 - Sensitivity analysis: N (%) of death possibly related to r-HAT or to Fexinidazole up to the end of hospitalisation – stage 2 r-HAT participants in the completer population
...

Sheet Labels
A1: Section | B1: Subsection | C1: DisplayMode | D1: InputID | E1: Include | F1: InputNumber | G1: Caption | H1: Figure | I1: FootNote | J1: Can You modify labels? | K1: Link
A2: Patient disposition | D2: sec1_scr_pat | F2: =ROW() - 1 -> 1 | G2: Screened participants | K2: =HYPERLINK("#'sec1_scr_pat'!A1","Open →") -> Open →
D3: sec1_inc_pat | F3: =ROW() - 1 -> 2 | G3: Participants disposition - included participants by study site | K3: =HYPERLINK("#'sec1_inc_pat'!A1","Open →") -> Open →
D4: sec1_inc_ITT_form | F4: =ROW() - 1 -> 3 | G4: Participants disposition - included participants by tablet form - ITT population | K4: =HYPERLINK("#'sec1_inc_ITT'!A1","Open →") -> Open →
D5: sec1_inc_ITT_stage | F5: =ROW() - 1 -> 4 | G5: Participants disposition - included participants by stage - ITT population | K5: =HYPERLINK("#'sec1_inc_ITT'!A1","Open →") -> Open →
D6: sec1_nb_vt | F6: =ROW() - 1 -> 5 | G6: Number of participants by type of visits performed - ITT population | K6: =HYPERLINK("#'sec1_nb_vt'!A1","Open →") -> Open →
A7: Baseline Characteristics | D7: sec2_bas_char_tot | F7: =ROW() - 1 -> 6 | G7: Preselection characteristics total - ITT population | K7: =HYPERLINK("#'sec2_bas_char_tot'!A1","Open →") -> Open →
D8: sec2_bas_char | F8: =ROW() - 1 -> 7 | G8: Preselection characteristics per weight band -ITT population | K8: =HYPERLINK("#'sec2_bas_char'!A1","Open →") -> Open →
B9: Palatability | D9: sec2_taste | F9: =ROW() - 1 -> 8 | G9: Treatment taste | K9: =HYPERLINK("#'sec2_taste'!A1","Open →") -> Open →
D10: sec2_swal | F10: =ROW() - 1 -> 9 | G10: Treatment swallowing
B11: Acceptability | D11: sec2_admin | F11: =ROW() - 1 -> 10 | G11: Treatment administration
D12: sec2_accept | F12: =ROW() - 1 -> 11 | G12: Treatment acceptance | K12: =HYPERLINK("#'sec2_accept'!A1","Open →") -> Open →
B13: Medical history | D13: sec2_mehs_soc | F13: =ROW() - 1 -> 12 | G13: Medical History by SOC/PT - ITT participants | H13: No | K13: =HYPERLINK("#'sec2_mehs_soc'!A1","Open →") -> Open →
B14: Laboratory diagnostic | D14: sec2_labdiag_tot | E14: No | F14: =ROW() - 1 -> 13 | G14: Laboratory diagnosis of Hat at preselection total - ITT population | K14: =HYPERLINK("#'sec2_labdiag'!A1","Open →") -> Open →
D15: sec2_labdiag | F15: =ROW() - 1 -> 14 | G15: Laboratory diagnosis of HAT at preselection per weight band - ITT population | K15: =HYPERLINK("#'sec2_labdiag'!A1","Open →") -> Open →
D16: sec2_res_mal_tot | E16: No | F16: =ROW() - 1 -> 15 | G16: Results of malaria test at preselection total - ITT population | K16: =HYPERLINK("#'sec2_res_mal'!A1","Open →") -> Open →
D17: sec2_res_mal | F17: =ROW() - 1 -> 16 | G17: Results of malaria test at preselection per weight band - ITT population | H17: No | K17: =HYPERLINK("#'sec2_res_mal'!A1","Open →") -> Open →
D18: sec2_vit_sg_tot | E18: No | F18: =ROW() - 1 -> 17 | G18: Vital signs at baseline total - ITT population | K18: =HYPERLINK("#'sec2_vit_sg'!A1","Open →") -> Open →
D19: sec2_vit_sg | F19: =ROW() - 1 -> 18 | G19: Vital signs at baseline per weight band - ITT population | K19: =HYPERLINK("#'sec2_vit_sg'!A1","Open →") -> Open →
D20: sec2_tsh_tot | E20: No | F20: =ROW() - 1 -> 19 | G20: Thyroid assessment at screening total - ITT population
D21: sec2_tsh | F21: =ROW() - 1 -> 20 | G21: Thyroid assesment at screening per weight band - ITT Population
B22: Signs and symptoms | D22: sec2_rhat_time | E22: No | F22: =ROW() - 1 -> 21 | G22: For each Signs and symptoms of HAT at baseline: Time from symptom n (%) | H22: No | I22: FS: First Symptoms, Sev. : Severity | K22: =HYPERLINK("#'sec2_rhat'!A1","Open →") -> Open →
D23: sec2_rhat_grade | E23: No | F23: =ROW() - 1 -> 22 | G23: For each Signs and symptoms of HAT at baseline: Continuous or interITTent and grade - ITT population n (%) | H23: No | I23: Tim. : Time from symptom | K23: =HYPERLINK("#'sec2_rhat'!A1","Open →") -> Open →
D24: sec2_otherss_first | E24: No | F24: =ROW() - 1 -> 23 | G24: For each Other Signs and symptoms of HAT at baseline: Time from symptom | I24: FS: First Symptoms, Sev. : Severity
D25: sec2_otherss_sev | E25: No | F25: =ROW() - 1 -> 24 | G25: For each Other Signs and symptoms of HAT at baseline: Continuous or interITTent and grade -ITT population n (%) | I25: Tim. : Time from symptom
B26: Physical and neurological assessment | D26: sec2_physex | F26: =ROW() - 1 -> 25 | G26: Physical examination at screening: n (%) of participants with normal / abnormal examination - ITT population | H26: No | K26: =HYPERLINK("#'sec2_physex'!A1","Open →") -> Open →
D27: sec2_neurex | F27: =ROW() - 1 -> 26 | G27: Neurological examinations at screening: n (%) of participants with anormal / abnormal examination - ITT population | H27: No | K27: =HYPERLINK("#'sec2_neurex'!A1","Open →") -> Open →
B28: Biochemistry | D28: sec2_platelets | F28: =ROW() - 1 -> 27 | G28: Platelets (10^3/µl): n (%) of participants with normal/abnormal results and descriptive statistics - ITT population
D29: sec2_leukocytes | F29: =ROW() - 1 -> 28 | G29: Leukocytes (10^3/µl): n (%) of participants with normal/abnormal results and descriptive statistics - ITT population
D30: sec2_neutrophils | F30: =ROW() - 1 -> 29 | G30: Neutrophils (%): n (%) of participants with normal/abnormal results and descriptive statistics - ITT population
D31: sec2_eosinophils | F31: =ROW() - 1 -> 30 | G31: Eosinophils (%): n (%) of participants with normal/abnormal results and descriptive statistics - ITT population
D32: sec2_basophils | F32: =ROW() - 1 -> 31 | G32: Basophils (%) : n (%) of participants with normal/abnormal results and descriptive statistics - ITT population
D33: sec2_lymphocytes | F33: =ROW() - 1 -> 32 | G33: Lymphocytes (%): n (%) of participants with normal/abnormal results and descriptive statistics - ITT population
D34: sec2_monocytes | F34: =ROW() - 1 -> 33 | G34: Monocytes (%): n (%) of participants with normal/abnormal results and descriptive statistics - ITT population
D35: sec2_hemo_1 | F35: =ROW() - 1 -> 34 | G35: n (%) of participants with normal/abnormal results and descriptive statistics for Hemoglobin– male (g/dL) in ITT population
D36: sec2_hemo_2 | F36: =ROW() - 1 -> 35 | G36: n (%) of participants with normal/abnormal results and descriptive statistics for Hemoglobin– female (g/dL) in ITT population
D37: sec2_sodium | F37: =ROW() - 1 -> 36 | G37: Sodium (mmol/L): n (%) of participants with normal/abnormal results and descriptive statistics - ITT population
D38: sec2_potassium | F38: =ROW() - 1 -> 37 | G38: Potassium (mmol/L): n (%) of participants with normal/abnormal results and descriptive statistics - ITT population
D39: sec2_bicarbonates | F39: =ROW() - 1 -> 38 | G39: Bicarbonates (mmol/L): n (%) of participants with normal/abnormal results and descriptive statistics - ITT population
D40: sec2_chloride | F40: =ROW() - 1 -> 39 | G40: Chloride (mmol/L): n (%) of participants with normal/abnormal results and descriptive statistics - ITT population
...

Sheet sec1_deviation
A1: label | B1: order | C1: id
A2: deviation 1 | B2: 1 | C2: 1
A3: **En tete 1** | B3: 2 | C3: 4
A4: deviation 2 | B4: 4 | C4: 2
A5: deviation 3 | B5: 3 | C5: 3

Sheet sec1_scr_pat
A1: label | B1: order | C1: id
A2: Screened | B2: 1 | C2: 1
A3: - Non Eligible | B3: 2 | C3: 2
A4: Reason | B4: 3 | C4: 3
A5: - Did not Sign the Informed Consent | B5: 4 | C5: 4
A6: - Did not sign assent | B6: 5 | C6: 5
A7: - <6 years old | B7: 6 | C7: 6
A8: - Not parasitologically confirmed T.b. rhodesiense infection | B8: 7 | C8: 7
A9: - No permanent address or not traceable | B9: 8 | C9: 8
A10: - Active clinically relevant medical conditions other than HAT | B10: 9 | C10: 9
A11: - Compromised general health | B11: 10 | C11: 10
A12: - First trimester of pregnancy | B12: 11 | C12: 11
A13: - Previously enrolled or previous treatment of acoziborole | B13: 12 | C13: 12
A14: - Included | B14: 13 | C14: 13

Sheet sec1_inc_pat
A1: label | B1: order | C1: id
A2: Included (ITT population) | B2: 1 | C2: 1
A3: Exposed (received at least one dose of Acoziborole) (ITT/safety population) | B3: 2 | C3: 2
A4: Evaluable population | B4: 3 | C4: 3

Sheet sec1_nb_vt
A1: label | B1: order | C1: id
A2: Screening | B2: 1 | C2: 2
A3: D1 | B3: 2 | C3: 3
A4: D5 | B4: 3 | C4: 4
A5: D11 | B5: 4 | C5: 5
A6: EOH | B6: 5 | C6: 6
A7: M3 | B7: 6 | C7: 7
A8: M6 | B8: 7 | C8: 8
A9: 1 unscheduled visit | B9: 8 | C9: 9
A10: 2 unscheduled visits | B10: 9 | C10: 10
A11: 3 or more unscheduled visits | B11: 10 | C11: 11

Sheet sec1_inc_mitt
A1: label | B1: order | C1: id
A2: Bandundu | B2: 1 | C2: 1
A3: Masi-Manimba | B3: 2 | C3: 2
A4: Dipumba | B4: 3 | C4: 3
A5: Katanda | B5: 4 | C5: 4
A6: Bagata | B6: 5 | C6: 5
A7: Dubreka | B7: 6 | C7: 6

Sheet sec2_bas_char_tot
A1: label | B1: order | C1: id
A2: Age in years \n median [Q1 ; Q3] (min/max) | B2: 2 | C2: 1
A3: Age in years \n N, mean (sd) | B3: 1 | C3: 2
A4: **Age Groups (in years)** | B4: 3 | C4: 3
A5: - [0 - 5) | B5: 4 | C5: 4
A6: - [5 - 10) | B6: 5 | C6: 5
A7: - >=10 | B7: 6 | C7: 6
A8: **Weight Bands (in Kg)** | B8: 7 | C8: 7
A9: - [10 - 20) | B9: 8 | C9: 8
A10: - [20 - 30) | B10: 9 | C10: 9
A11: - [30 - 40) | B11: 10 | C11: 10
A12: Male - n (%) | B12: 11 | C12: 11
A13: - Male > 2 years | B13: 12 | C13: 12
... A17: - Female <= 2 years | B17: 16 | C17: 16

Sheet sec2_bas_char
A1: label | B1: order | C1: id
A2: Age in years \n N, median [Q1 ; Q3] (min/max) | B2: 2 | C2: 1
A3: Age in years \n N, mean (sd) | B3: 1 | C3: 2
A4: **Age Groups (in years)** | B4: 3 | C4: 3
A5: - (0 - 5] | B5: 4 | C5: 4
A6: - (5-10] | B6: 5 | C6: 5
A7: - > 10 | B7: 6 | C7: 6
A8: Male - n (%) | B8: 7 | C8: 7
A9: Female - n (%) | B9: 10 | C9: 10

Sheet sec2_labdiag
A1: label | B1: order | C1: id
A2: **Blood and lymph node aspirate tests** | B2: 1 | C2: 1
A3: mAECT -n (%) | B3: 2 | C3: 2
A4: - Positive | B4: 3 | C4: 3
A5: - Negative | B5: 4 | C5: 4
A6: - Not done | B6: 5 | C6: 5
A7: - Missing | B7: 6 | C7: 6
A8: mAECT-BC - n (%) | B8: 7 | C8: 7
A9: - Positive | B9: 8 | C9: 8
A10: - Negative | B10: 9 | C10: 9
A11: - Not done | B11: 10 | C11: 10
A12: - Missing | B12: 11 | C12: 11
A13: Lymph node aspirate - n (%) | B13: 12 | C13: 12
... A44: - Missing | B44: 43 | C44: 43

Sheet sec2_res_mal
A1: label | B1: order | C1: id
A2: RDT for Malaria - n (%) | B2: 1 | C2: 1
A3: - Positive | B3: 2 | C3: 2
A4: - Negative | B4: 3 | C4: 3
A5: - Not done | B5: 4 | C5: 4
A6: - Missing | B6: 5 | C6: 5
A7: Thick smear test - n (%) | B7: 6 | C7: 6
A8: - Positive | B8: 7 | C8: 7
A9: - Negative | B9: 8 | C9: 8
A10: - Not done | B10: 9 | C10: 9
A11: - Missing | B11: 10 | C11: 10

Sheet sec2_taste
A1: label | B1: order | C1: id
A2: Very unpleasant taste | B2: 1 | C2: 1
A3: Unpleasant taste | B3: 2 | C3: 2
A4: Neutral taste | B4: 3 | C4: 3
A5: Pleasant taste | B5: 4 | C5: 4
A6: Very pleasant taste | B6: 5 | C6: 5
A7: Missing | B7: 6 | C7: 6

Sheet sec2_accept
A1: label | B1: order | C1: id
A2: Rejected | B2: 1 | C2: 1
A3: With difficulty | B3: 2 | C3: 2
A4: Acceptable | B4: 3 | C4: 3
A5: Good | B5: 4 | C5: 4
A6: Very good | B6: 5 | C6: 5
A7: Missing | B7: 6 | C7: 6

Sheet sec2_acc
A1: label | B1: order | C1: id
A2: Very difficult | B2: 1 | C2: 1
A3: Difficult | B3: 2 | C3: 2
A4: Neutral | B4: 3 | C4: 3
A5: Easy | B5: 4 | C5: 4
A6: Very easy | B6: 5 | C6: 5
A7: Missing | B7: 6 | C7: 6

Sheet sec2_vit_sg
A1: label | B1: order | C1: id
A2: **Temperature ( C )** | B2: 1 | C2: 1
A3: - N, mean (sd) | B3: 2 | C3: 2
A4: - median [Q1; Q3] \n (min/max) | B4: 3 | C4: 3
A5: **Heart Rate** | B5: 4 | C5: 4
A6: - N, mean (sd) | B6: 5 | C6: 5
A7: - median [Q1; Q3] \n (min/max) | B7: 6 | C7: 6
A8: **Respiratory rate** | B8: 7 | C8: 7
A9: - N, mean (sd) | B9: 8 | C9: 8
A10: - median [Q1; Q3] \n (min/max) | B10: 9 | C10: 9
A11: **SBP** | B11: 10 | C11: 10
A12: - N, mean (sd) | B12: 11 | C12: 11
A13: - median [Q1; Q3] \n (min/max) | B13: 12 | C13: 12
... A34: Missing | B34: 33 | C34: 33

Sheet sec2_rhat
A1: label | B1: id | C1: order
A2: Total | B2: 1 | C2: 0
A3: Headaches | B3: 2 | C3: 1
A4: Drowsiness | B4: 3 | C4: 2
A5: Asthenia | B5: 4 | C5: 3
A6: Impotence | B6: 5 | C6: 4
A7: Amenorrhea | B7: 6 | C7: 5
A8: Convulsion | B8: 7 | C8: 6
A9: Fever | B9: 8 | C9: 7
A10: Insomnia | B10: 9 | C10: 8
A11: Behavioural disorders | B11: 10 | C11: 9
A12: Language disorders | B12: 11 | C12: 10
A13: Pruritus | B13: 12 | C13: 11
... A19: Slimming/weight loss | B19: 18 | C19: 17

Sheet sec2_mehs_soc
A1: label | B1: order | C1: id
A2: SOC1 | B2: 1 | C2: 1
A3: PT | B3: 2 | C3: 2
A4: PT | B4: 3 | C4: 3
A5: SOC2… | B5: 4 | C5: 4

Sheet sec2_physex
A1: label | B1: order | C1: id
A2: **Patients all normal** | B2: 1 | C2: 1
A3: **Patients with at least one abnormal** | B3: 2 | C3: 2
A4: **Patients with at least one missing** | B4: 3 | C4: 3
A5: **Patients with 5 or more abnormalities** | B5: 4 | C5: 4
A6: **Head and neck** | B6: 5 | C6: 5
A7: Eyeball - n (%) | B7: 6 | C7: 6
A8: - Normal | B8: 7 | C8: 7
A9: - Enophthalmos | B9: 8 | C9: 8
A10: - Exophthalmos | B10: 9 | C10: 9
A11: - Other | B11: 10 | C11: 10
A12: - Missing | B12: 11 | C12: 11
A13: Tunica conjunctiva palpebrarum - n (%) | B13: 12 | C13: 12
... A85: - Missing | B85: 84 | C85: 84

Sheet sec2_neurex
A1: label | B1: order | C1: id
A2: **Patients all normal** | B2: 1 | C2: 1
A3: **Patients with at least one abnormal** | B3: 2 | C3: 2
A4: **Patients with at least one missing** | B4: 3 | C4: 3
A5: **Patients with 5 or more abnormalities** | B5: 4 | C5: 4
A6: **Patients with specific conditions** | B6: 5 | C6: 5
A7: **Psychiatric observation** | B7: 6 | C7: 6
A8: Verbal flux - n (%) | B8: 7 | C8: 7
A9: - Normal | B9: 8 | C9: 8
A10: - Reduced | B10: 9 | C10: 9
A11: - Excessive | B11: 10 | C11: 10
A12: - NA | B12: 11 | C12: 11
A13: - Missing | B13: 12 | C13: 12
... A162: **Other neurological abnormalities** | B162: 161 | C162: 161

Sheet sec2_hema
A1: label | B1: order | C1: id
A2: N, mean (sd) | B2: 1 | C2: 1
A3: Median [Q1 ; Q3] \n (min/max) | B3: 2 | C3: 2
A4: Normal - n (%) | B4: 3 | C4: 3
A5: Abnormal - n (%) | B5: 4 | C5: 4
A6: - Abnormal not CS | B6: 5 | C6: 5
A7: - Abnormal CS | B7: 6 | C7: 6
A8: Missing - n (%) | B8: 7 | C8: 7

Sheet sec2_hemagluc
A1: label | B1: order | C1: id
A2: N, mean (sd) | B2: 1 | C2: 1
A3: median [Q1 ; Q3] \n (min/max) | B3: 2 | C3: 2
A4: Normal - n (%) | B4: 3 | C4: 3
A5: Abnormal - n (%) | B5: 4 | C5: 4
A6: - Abnormal not CS (fasting conditions) | B6: 5 | C6: 5
A7: - Abnormal not CS (not on fasting conditions) | B7: 6 | C7: 6
A8: - Abnormal CS (fasting conditions) | B8: 7 | C8: 7
A9: - Abnormal CS (not on fasting conditions) | B9: 8 | C9: 8
A10: Missing - n (%) | B10: 9 | C10: 9

Sheet sec2_ecg
A1: label | B1: order | C1: id
A2: Normal | B2: 1 | C2: 1
A3: Abnormal | B3: 2 | C3: 2
A4: - Abnormal not CS | B4: 3 | C4: 3
A5: - Abnormal CS | B5: 4 | C5: 4
A6: Missing | B6: 5 | C6: 5

Sheet sec2_hs_rhat
A1: label | B1: order | C1: id
A2: History of HAT - n (%) | B2: 1 | C2: 1
A3: Stage 1 - n (%) | B3: 2 | C3: 2
A4: Stage 2 - n (%) | B4: 3 | C4: 3
A5: **Treatment received** | B5: 4 | C5: 4

Sheet sec3_patdev1
A1: label | B1: id | C1: order
A2: Patients who did not complete the full course of treatment | B2: 1 | C2: 1
A3: Patients not fully compliant | B3: 2 | C3: 2
A4: Patients who did not take at least one treatment during a meal | B4: 3 | C4: 3

Sheet sec3_patdev2
A1: label | B1: id | C1: order
A2: Patients who had at least one re-administration due to vomiting | B2: 4 | C2: 4
A3: Patients who had at least one re-administration due to other reason | B3: 5 | C3: 5
A4: Number of re-administration(s) by patient - median [Q1 ; Q3] (min/max) | B4: 6 | C4: 6

Sheet sec4_wbc
A1: label | B1: id | C1: order
A2: - WBC / mm3 CSF N, median (IQR) (min/max) | B2: 1 | C2: 1

Sheet sec5_ssrhat
A1: label | B1: id | C1: order
A2: Headaches | B2: 1 | C2: 1
A3: Drowsiness | B3: 2 | C3: 2
A4: Asthenia | B4: 3 | C4: 3
A5: Convulsion | B5: 4 | C5: 4
A6: Fever | B6: 5 | C6: 5
A7: Insomnia | B7: 6 | C7: 6
A8: Behavioural disorders | B8: 7 | C8: 7
A9: Language disorders | B9: 8 | C9: 8
A10: Pruritus | B10: 9 | C10: 9
A11: Tremor | B11: 10 | C11: 10
A12: Gait disorders | B12: 11 | C12: 11
A13: Anorexia | B13: 12 | C13: 12
... A17: Total | B17: 16 | C17: 16

Sheet sec5_vitsigns
A1: label | B1: id | C1: order
A2: - N, Mean (SD) | B2: 1 | C2: 1
A3: - Median [Q1 ; Q3] (min/max) | B3: 2 | C3: 2
A4: Change from baseline | B4: 3 | C4: 3
A5: - N, Mean (SD) | B5: 4 | C5: 4
A6: - Median [Q1 ; Q3] (min/max) | B6: 5 | C6: 5

Sheet sec5_genstatus
A1: label | B1: id | C1: order
A2: Good | B2: 1 | C2: 2
A3: Altered | B3: 2 | C3: 3
A4: Bad | B4: 3 | C4: 4
A5: Missing | B5: 4 | C5: 5

Sheet sec5_aenumb
A1: label | B1: id | C1: order
A2: - During Screening | B2: 1 | C2: 1
A3: - During hospitalization | B3: 2 | C3: 2
A4: - AE related | B4: 3 | C4: 3
A5: - Serious AE | B5: 4 | C5: 4
A6: - Not related and not serious AE | B6: 5 | C6: 5
A7: - Mild or moderate AE | B7: 6 | C7: 6
A8: - Grade >= 3 | B8: 7 | C8: 7
A9: - At 3 Month follow up | B9: 8 | C9: 8
A10: - AE related | B10: 9 | C10: 9
A11: - Serious AE | B11: 10 | C11: 10
A12: - Not related and not serious AE | B12: 11 | C12: 11
A13: - Mild or moderate AE | B13: 12 | C13: 12
... A25: - Death not related to gambiense | B25: 24 | C25: 24

Sheet sec5_aetreat
A1: label | B1: id | C1: order
A2: - **All Adverse Events** | B2: 1 | C2: 1
A3: - AE Related | B3: 2 | C3: 2
A4: - SAE | B4: 3 | C4: 3
A5: - Not related and not serious AE | B5: 4 | C5: 4
A6: - Grade >= 3 | B6: 5 | C6: 5
A7: - Mild or moderate AE | B7: 6 | C7: 6
A8: - Adverse Event leading to death | B8: 7 | C8: 7
A9: - Death related to gambiense | B9: 8 | C9: 8
A10: - Death not related to gambiense | B10: 9 | C10: 9
